2025-09-02 13:03:02,992 - ai_analysis_engine.orchestrator.orchestrator - INFO - Orchestrator initialized successfully
2025-09-02 13:03:02,992 - ai_analysis_engine.orchestrator.orchestrator - INFO - Starting analysis for algorithm_output_id: 38
2025-09-02 13:03:02,992 - ai_analysis_engine.orchestrator.orchestrator - ERROR - Failed to load evaluation data: 評価データの取得に失敗しました: 該当algorithm_output_ID=38の評価データCSVが見つかりません
2025-09-02 13:03:02,992 - ai_analysis_engine.orchestrator.orchestrator - ERROR - Analysis failed: 評価データの取得に失敗しました: 該当algorithm_output_ID=38の評価データCSVが見つかりません
Traceback (most recent call last):
  File "C:\workspace\ImproveAlgorithmDevelopment\ai_analysis_engine\src\ai_analysis_engine\utils\data_loader.py", line 94, in get_evaluation_data
    evaluation_df = self.load_evaluation_results(algorithm_output_dir)
  File "C:\workspace\ImproveAlgorithmDevelopment\ai_analysis_engine\src\ai_analysis_engine\utils\data_loader.py", line 121, in load_evaluation_results
    raise FileNotFoundError(f"評価結果ファイルが見つかりません: {result_path}")
FileNotFoundError: 評価結果ファイルが見つかりません: ..\DataWareHouse\03_algorithm_output\v0.1.0\e2e

During handling of the above exception, another exception occurred:

Traceback (most recent call last):
  File "C:\workspace\ImproveAlgorithmDevelopment\ai_analysis_engine\src\ai_analysis_engine\utils\data_loader.py", line 97, in get_evaluation_data
    evaluation_df = self._load_eval_data_from_evaluation_tables(algorithm_output_id)
  File "C:\workspace\ImproveAlgorithmDevelopment\ai_analysis_engine\src\ai_analysis_engine\utils\data_loader.py", line 164, in _load_eval_data_from_evaluation_tables
    raise FileNotFoundError(
FileNotFoundError: 該当algorithm_output_ID=38の評価データCSVが見つかりません

During handling of the above exception, another exception occurred:

Traceback (most recent call last):
  File "C:\workspace\ImproveAlgorithmDevelopment\ai_analysis_engine\src\ai_analysis_engine\orchestrator\orchestrator.py", line 86, in run_analysis
    evaluation_data = self._load_evaluation_data(algorithm_output_id)
  File "C:\workspace\ImproveAlgorithmDevelopment\ai_analysis_engine\src\ai_analysis_engine\orchestrator\orchestrator.py", line 132, in _load_evaluation_data
    metadata_df = self.datawarehouse.get_evaluation_data(algorithm_output_id)
  File "C:\workspace\ImproveAlgorithmDevelopment\ai_analysis_engine\src\ai_analysis_engine\utils\data_loader.py", line 106, in get_evaluation_data
    raise RuntimeError(f"評価データの取得に失敗しました: {str(e)}")
RuntimeError: 評価データの取得に失敗しました: 該当algorithm_output_ID=38の評価データCSVが見つかりません
