2025-09-02 13:25:27,974 - ai_analysis_engine.orchestrator.orchestrator - INFO - Orchestrator initialized successfully
2025-09-02 13:25:27,974 - ai_analysis_engine.orchestrator.orchestrator - INFO - Starting analysis for algorithm_output_id: 36
2025-09-02 13:25:27,975 - ai_analysis_engine.orchestrator.orchestrator - INFO - Loaded evaluation data: 3 records
2025-09-02 13:25:27,975 - ai_analysis_engine.orchestrator.orchestrator - INFO - Running performance analysis...
2025-09-02 13:25:27,986 - ai_analysis_engine.orchestrator.orchestrator - ERROR - Analysis failed: 'left_eye_open'
Traceback (most recent call last):
  File "C:\workspace\ImproveAlgorithmDevelopment\ai_analysis_engine\.venv\lib\site-packages\pandas\core\indexes\base.py", line 3812, in get_loc
    return self._engine.get_loc(casted_key)
  File "pandas/_libs/index.pyx", line 167, in pandas._libs.index.IndexEngine.get_loc
  File "pandas/_libs/index.pyx", line 196, in pandas._libs.index.IndexEngine.get_loc
  File "pandas/_libs/hashtable_class_helper.pxi", line 7088, in pandas._libs.hashtable.PyObjectHashTable.get_item
  File "pandas/_libs/hashtable_class_helper.pxi", line 7096, in pandas._libs.hashtable.PyObjectHashTable.get_item
KeyError: 'left_eye_open'

The above exception was the direct cause of the following exception:

Traceback (most recent call last):
  File "C:\workspace\ImproveAlgorithmDevelopment\ai_analysis_engine\src\ai_analysis_engine\orchestrator\orchestrator.py", line 91, in run_analysis
    performance_results = self.performance_analyzer.analyze_performance(evaluation_data)
  File "C:\workspace\ImproveAlgorithmDevelopment\ai_analysis_engine\src\ai_analysis_engine\performance_analyzer\performance_analyzer.py", line 59, in analyze_performance
    df_with_expectations = self.expectation_generator.detect_continuous_closure(df)
  File "C:\workspace\ImproveAlgorithmDevelopment\ai_analysis_engine\src\ai_analysis_engine\utils\expectation_generator.py", line 117, in detect_continuous_closure
    'left_eye_open': row['left_eye_open'],
  File "C:\workspace\ImproveAlgorithmDevelopment\ai_analysis_engine\.venv\lib\site-packages\pandas\core\series.py", line 1130, in __getitem__
    return self._get_value(key)
  File "C:\workspace\ImproveAlgorithmDevelopment\ai_analysis_engine\.venv\lib\site-packages\pandas\core\series.py", line 1246, in _get_value
    loc = self.index.get_loc(label)
  File "C:\workspace\ImproveAlgorithmDevelopment\ai_analysis_engine\.venv\lib\site-packages\pandas\core\indexes\base.py", line 3819, in get_loc
    raise KeyError(key) from err
KeyError: 'left_eye_open'
