2025-09-02 13:23:09,312 - ai_analysis_engine.orchestrator.orchestrator - INFO - Orchestrator initialized successfully
2025-09-02 13:23:09,312 - ai_analysis_engine.orchestrator.orchestrator - INFO - Starting analysis for algorithm_output_id: 36
2025-09-02 13:23:09,338 - ai_analysis_engine.orchestrator.orchestrator - ERROR - Failed to load evaluation data: 'dict' object has no attribute 'iloc'
2025-09-02 13:23:09,338 - ai_analysis_engine.orchestrator.orchestrator - ERROR - Analysis failed: 'dict' object has no attribute 'iloc'
Traceback (most recent call last):
  File "C:\workspace\ImproveAlgorithmDevelopment\ai_analysis_engine\src\ai_analysis_engine\orchestrator\orchestrator.py", line 86, in run_analysis
    evaluation_data = self._load_evaluation_data(algorithm_output_id)
  File "C:\workspace\ImproveAlgorithmDevelopment\ai_analysis_engine\src\ai_analysis_engine\orchestrator\orchestrator.py", line 133, in _load_evaluation_data
    metadata = metadata_df.iloc[0].to_dict()
AttributeError: 'dict' object has no attribute 'iloc'
