2025-09-29 14:59:27,781 - ai_analysis_engine.orchestrator.orchestrator - INFO - Orchestrator initialized successfully
2025-09-29 14:59:27,782 - ai_analysis_engine.orchestrator.orchestrator - INFO - Starting analysis for evaluation_result_id: 3
2025-09-29 14:59:27,821 - ai_analysis_engine.orchestrator.orchestrator - INFO - Task DF mode - Algorithm ID: 3
2025-09-29 14:59:27,823 - ai_analysis_engine.orchestrator.orchestrator - INFO - Retrieved algorithm output for task DF: True
2025-09-29 14:59:27,823 - ai_analysis_engine.orchestrator.orchestrator - INFO - Retrieved core output for task DF: True
2025-09-29 14:59:27,824 - ai_analysis_engine.orchestrator.orchestrator - INFO - Loaded evaluation data: 20 records
2025-09-29 14:59:27,824 - ai_analysis_engine.orchestrator.orchestrator - INFO - Running performance analysis...
2025-09-29 14:59:31,282 - ai_analysis_engine.orchestrator.orchestrator - INFO - Performance analysis completed: {'total_samples': 20, 'accuracy': 0.45, 'correct_predictions': 9, 'incorrect_predictions': 11}
2025-09-29 14:59:31,283 - ai_analysis_engine.orchestrator.orchestrator - INFO - Running instance analysis...
2025-09-29 14:59:31,950 - ai_analysis_engine.orchestrator.orchestrator - INFO - Instance analysis completed: 11 instances analyzed
2025-09-29 14:59:31,951 - ai_analysis_engine.orchestrator.orchestrator - ERROR - Analysis failed: 'NoneType' object has no attribute 'get'
Traceback (most recent call last):
  File "C:\workspace\ImproveAlgorithmDevelopment\ai_analysis_engine\src\ai_analysis_engine\orchestrator\orchestrator.py", line 184, in run_analysis_by_evaluation_result
    integrated_results = self._integrate_results(performance_results, instance_results)
  File "C:\workspace\ImproveAlgorithmDevelopment\ai_analysis_engine\src\ai_analysis_engine\orchestrator\orchestrator.py", line 357, in _integrate_results
    'recommendations': self._generate_recommendations(performance_results, instance_results),
  File "C:\workspace\ImproveAlgorithmDevelopment\ai_analysis_engine\src\ai_analysis_engine\orchestrator\orchestrator.py", line 378, in _generate_recommendations
    error_instances = [result for result in instance_results
  File "C:\workspace\ImproveAlgorithmDevelopment\ai_analysis_engine\src\ai_analysis_engine\orchestrator\orchestrator.py", line 379, in <listcomp>
    if result.get('summary', {}).get('has_errors', False)]
AttributeError: 'NoneType' object has no attribute 'get'
