2025-09-02 13:41:23,863 - ai_analysis_engine.orchestrator.orchestrator - INFO - Orchestrator initialized successfully
2025-09-02 13:41:23,863 - ai_analysis_engine.orchestrator.orchestrator - INFO - Starting analysis for evaluation_result_id: 3
2025-09-02 13:41:23,918 - ai_analysis_engine.orchestrator.orchestrator - INFO - Loaded evaluation data: 20 records
2025-09-02 13:41:23,918 - ai_analysis_engine.orchestrator.orchestrator - INFO - Running performance analysis...
2025-09-02 13:41:23,918 - ai_analysis_engine.orchestrator.orchestrator - ERROR - Analysis failed: 'frame_num'
Traceback (most recent call last):
  File "C:\workspace\ImproveAlgorithmDevelopment\ai_analysis_engine\src\ai_analysis_engine\orchestrator\orchestrator.py", line 139, in run_analysis_by_evaluation_result
    performance_results = self.performance_analyzer.analyze_performance(evaluation_data)
  File "C:\workspace\ImproveAlgorithmDevelopment\ai_analysis_engine\src\ai_analysis_engine\performance_analyzer\performance_analyzer.py", line 59, in analyze_performance
    df_with_expectations = self.expectation_generator.detect_continuous_closure(df)
  File "C:\workspace\ImproveAlgorithmDevelopment\ai_analysis_engine\src\ai_analysis_engine\utils\expectation_generator.py", line 108, in detect_continuous_closure
    result_df = result_df.sort_values('frame_num').reset_index(drop=True)
  File "C:\workspace\ImproveAlgorithmDevelopment\ai_analysis_engine\.venv\lib\site-packages\pandas\core\frame.py", line 7196, in sort_values
    k = self._get_label_or_level_values(by[0], axis=axis)
  File "C:\workspace\ImproveAlgorithmDevelopment\ai_analysis_engine\.venv\lib\site-packages\pandas\core\generic.py", line 1911, in _get_label_or_level_values
    raise KeyError(key)
KeyError: 'frame_num'
