2025-09-02 12:59:31,512 - ai_analysis_engine.orchestrator.orchestrator - INFO - Orchestrator initialized successfully
2025-09-02 12:59:31,513 - ai_analysis_engine.orchestrator.orchestrator - INFO - Starting analysis for algorithm_output_id: None
2025-09-02 12:59:31,520 - ai_analysis_engine.orchestrator.orchestrator - ERROR - Failed to load evaluation data: 評価データの取得に失敗しました: 'str' object has no attribute 'parent'
2025-09-02 12:59:31,520 - ai_analysis_engine.orchestrator.orchestrator - ERROR - Analysis failed: 評価データの取得に失敗しました: 'str' object has no attribute 'parent'
Traceback (most recent call last):
  File "C:\workspace\ImproveAlgorithmDevelopment\ai_analysis_engine\src\ai_analysis_engine\utils\data_loader.py", line 89, in get_evaluation_data
    evaluation_df = self.load_evaluation_results(algorithm_output_dir)
  File "C:\workspace\ImproveAlgorithmDevelopment\ai_analysis_engine\src\ai_analysis_engine\utils\data_loader.py", line 110, in load_evaluation_results
    result_path = self.db_path.parent / algorithm_output_dir
AttributeError: 'str' object has no attribute 'parent'

During handling of the above exception, another exception occurred:

Traceback (most recent call last):
  File "C:\workspace\ImproveAlgorithmDevelopment\ai_analysis_engine\src\ai_analysis_engine\orchestrator\orchestrator.py", line 86, in run_analysis
    evaluation_data = self._load_evaluation_data(algorithm_output_id)
  File "C:\workspace\ImproveAlgorithmDevelopment\ai_analysis_engine\src\ai_analysis_engine\orchestrator\orchestrator.py", line 132, in _load_evaluation_data
    metadata_df = self.datawarehouse.get_evaluation_data(algorithm_output_id)
  File "C:\workspace\ImproveAlgorithmDevelopment\ai_analysis_engine\src\ai_analysis_engine\utils\data_loader.py", line 98, in get_evaluation_data
    raise RuntimeError(f"評価データの取得に失敗しました: {str(e)}")
RuntimeError: 評価データの取得に失敗しました: 'str' object has no attribute 'parent'
